Workbook

Sheet Read me
B1: Program scoping workbook
B4: What it's for
B5: Size every asset, system and deliverable a program touches, so the timeline, resourcing, cost and risk rest
B6: on evidence rather than guesses. The example program here is a website and customer portal migration.
B8: How to complete it
B9: 1. Each function has its own tab with a few example rows and blank rows. Replace the examples and add
B10: what's missing. Mark rows Not applicable rather than deleting them.
B11: 2. Split a row when its owner, effort, timing or risk differ from the rest.
B12: 3. Effort: enter active quantity, % needing change, setup hours, average hours per item and QA hours.
B13: The tab works out items to update, internal hours and FTE days.
B14: 4. Cost: add a blended hourly rate and any external or vendor cost. Total cost combines both.
B15: 5. Risk and timing: flag customer action, approvals, lead time, risk and whether old and new can run together.
... B26: All names and numbers in this template are examples. Estimate conservatively and note your assumptions.
B28: Example input cell | C28: Example calculated cell

Sheet Summary
B1: Program scope summary
B4: Scope, effort, cost and risk by function. It fills in from the function tabs.
B6: Internal hours | D6: FTE days | F6: Total estimated cost | H6: Customer action items
B7: =E27 | D7: =F27 | F7: =H27 | H7: =J27
B10: By function
B11: Function | C11: Scoped lines | D11: Items to update | E11: Internal hours | F11: FTE days | G11: External cost | H11: Total estimated cost | I11: High or critical risk | J11: Customer action
B12: Marketing | C12: =COUNTA(Marketing!C10:C69) | D12: =SUM(Marketing!J10:J69) | E12: =SUM(Marketing!P10:P69) | F12: =SUM(Marketing!Q10:Q69) | G12: =SUM(Marketing!T10:T69) | H12: =SUM(Marketing!U10:U69) | I12: =COUNTIF(Marketing!AB10:AB69,"High")+COUNTIF(Marketing!AB10:AB69,"Critical") | J12: =COUNTIF(Marketing!W10:W69,"Yes")
B13: Product | C13: =COUNTA(Product!C10:C69) | D13: =SUM(Product!J10:J69) | E13: =SUM(Product!P10:P69) | F13: =SUM(Product!Q10:Q69) | G13: =SUM(Product!T10:T69) | H13: =SUM(Product!U10:U69) | I13: =COUNTIF(Product!AB10:AB69,"High")+COUNTIF(Product!AB10:AB69,"Critical") | J13: =COUNTIF(Product!W10:W69,"Yes")
B14: Engineering | C14: =COUNTA(Engineering!C10:C69) | D14: =SUM(Engineering!J10:J69) | E14: =SUM(Engineering!P10:P69) | F14: =SUM(Engineering!Q10:Q69) | G14: =SUM(Engineering!T10:T69) | H14: =SUM(Engineering!U10:U69) | I14: =COUNTIF(Engineering!AB10:AB69,"High")+COUNTIF(Engineering!AB10:AB69,"Critical") | J14: =COUNTIF(Engineering!W10:W69,"Yes")
B15: IT & Security | C15: =COUNTA('IT & Security'!C10:C69) | D15: =SUM('IT & Security'!J10:J69) | E15: =SUM('IT & Security'!P10:P69) | F15: =SUM('IT & Security'!Q10:Q69) | G15: =SUM('IT & Security'!T10:T69) | H15: =SUM('IT & Security'!U10:U69) | I15: =COUNTIF('IT & Security'!AB10:AB69,"High")+COUNTIF('IT & Security'!AB10:AB69,"Critical") | J15: =COUNTIF('IT & Security'!W10:W69,"Yes")
B16: Legal & Privacy | C16: =COUNTA('Legal & Privacy'!C10:C69) | D16: =SUM('Legal & Privacy'!J10:J69) | E16: =SUM('Legal & Privacy'!P10:P69) | F16: =SUM('Legal & Privacy'!Q10:Q69) | G16: =SUM('Legal & Privacy'!T10:T69) | H16: =SUM('Legal & Privacy'!U10:U69) | I16: =COUNTIF('Legal & Privacy'!AB10:AB69,"High")+COUNTIF('Legal & Privacy'!AB10:AB69,"Critical") | J16: =COUNTIF('Legal & Privacy'!W10:W69,"Yes")
B17: Sales Enablement | C17: =COUNTA('Sales Enablement'!C10:C69) | D17: =SUM('Sales Enablement'!J10:J69) | E17: =SUM('Sales Enablement'!P10:P69) | F17: =SUM('Sales Enablement'!Q10:Q69) | G17: =SUM('Sales Enablement'!T10:T69) | H17: =SUM('Sales Enablement'!U10:U69) | I17: =COUNTIF('Sales Enablement'!AB10:AB69,"High")+COUNTIF('Sales Enablement'!AB10:AB69,"Critical") | J17: =COUNTIF('Sales Enablement'!W10:W69,"Yes")
B18: Sales & RevOps | C18: =COUNTA('Sales & RevOps'!C10:C69) | D18: =SUM('Sales & RevOps'!J10:J69) | E18: =SUM('Sales & RevOps'!P10:P69) | F18: =SUM('Sales & RevOps'!Q10:Q69) | G18: =SUM('Sales & RevOps'!T10:T69) | H18: =SUM('Sales & RevOps'!U10:U69) | I18: =COUNTIF('Sales & RevOps'!AB10:AB69,"High")+COUNTIF('Sales & RevOps'!AB10:AB69,"Critical") | J18: =COUNTIF('Sales & RevOps'!W10:W69,"Yes")
B19: Customer Success | C19: =COUNTA('Customer Success'!C10:C69) | D19: =SUM('Customer Success'!J10:J69) | E19: =SUM('Customer Success'!P10:P69) | F19: =SUM('Customer Success'!Q10:Q69) | G19: =SUM('Customer Success'!T10:T69) | H19: =SUM('Customer Success'!U10:U69) | I19: =COUNTIF('Customer Success'!AB10:AB69,"High")+COUNTIF('Customer Success'!AB10:AB69,"Critical") | J19: =COUNTIF('Customer Success'!W10:W69,"Yes")
B20: Professional Services | C20: =COUNTA('Professional Services'!C10:C69) | D20: =SUM('Professional Services'!J10:J69) | E20: =SUM('Professional Services'!P10:P69) | F20: =SUM('Professional Services'!Q10:Q69) | G20: =SUM('Professional Services'!T10:T69) | H20: =SUM('Professional Services'!U10:U69) | I20: =COUNTIF('Professional Services'!AB10:AB69,"High")+COUNTIF('Professional Services'!AB10:AB69,"Critical") | J20: =COUNTIF('Professional Services'!W10:W69,"Yes")
B21: Customer Support | C21: =COUNTA('Customer Support'!C10:C69) | D21: =SUM('Customer Support'!J10:J69) | E21: =SUM('Customer Support'!P10:P69) | F21: =SUM('Customer Support'!Q10:Q69) | G21: =SUM('Customer Support'!T10:T69) | H21: =SUM('Customer Support'!U10:U69) | I21: =COUNTIF('Customer Support'!AB10:AB69,"High")+COUNTIF('Customer Support'!AB10:AB69,"Critical") | J21: =COUNTIF('Customer Support'!W10:W69,"Yes")
B22: Pre-Sales | C22: =COUNTA('Pre-Sales'!C10:C69) | D22: =SUM('Pre-Sales'!J10:J69) | E22: =SUM('Pre-Sales'!P10:P69) | F22: =SUM('Pre-Sales'!Q10:Q69) | G22: =SUM('Pre-Sales'!T10:T69) | H22: =SUM('Pre-Sales'!U10:U69) | I22: =COUNTIF('Pre-Sales'!AB10:AB69,"High")+COUNTIF('Pre-Sales'!AB10:AB69,"Critical") | J22: =COUNTIF('Pre-Sales'!W10:W69,"Yes")
B23: Partners | C23: =COUNTA(Partners!C10:C69) | D23: =SUM(Partners!J10:J69) | E23: =SUM(Partners!P10:P69) | F23: =SUM(Partners!Q10:Q69) | G23: =SUM(Partners!T10:T69) | H23: =SUM(Partners!U10:U69) | I23: =COUNTIF(Partners!AB10:AB69,"High")+COUNTIF(Partners!AB10:AB69,"Critical") | J23: =COUNTIF(Partners!W10:W69,"Yes")
B24: HR | C24: =COUNTA(HR!C10:C69) | D24: =SUM(HR!J10:J69) | E24: =SUM(HR!P10:P69) | F24: =SUM(HR!Q10:Q69) | G24: =SUM(HR!T10:T69) | H24: =SUM(HR!U10:U69) | I24: =COUNTIF(HR!AB10:AB69,"High")+COUNTIF(HR!AB10:AB69,"Critical") | J24: =COUNTIF(HR!W10:W69,"Yes")
B25: Finance & Procurement | C25: =COUNTA('Finance & Procurement'!C10:C69) | D25: =SUM('Finance & Procurement'!J10:J69) | E25: =SUM('Finance & Procurement'!P10:P69) | F25: =SUM('Finance & Procurement'!Q10:Q69) | G25: =SUM('Finance & Procurement'!T10:T69) | H25: =SUM('Finance & Procurement'!U10:U69) | I25: =COUNTIF('Finance & Procurement'!AB10:AB69,"High")+COUNTIF('Finance & Procurement'!AB10:AB69,"Critical") | J25: =COUNTIF('Finance & Procurement'!W10:W69,"Yes")
B26: Executive & Strategy | C26: =COUNTA('Executive & Strategy'!C10:C69) | D26: =SUM('Executive & Strategy'!J10:J69) | E26: =SUM('Executive & Strategy'!P10:P69) | F26: =SUM('Executive & Strategy'!Q10:Q69) | G26: =SUM('Executive & Strategy'!T10:T69) | H26: =SUM('Executive & Strategy'!U10:U69) | I26: =COUNTIF('Executive & Strategy'!AB10:AB69,"High")+COUNTIF('Executive & Strategy'!AB10:AB69,"Critical") | J26: =COUNTIF('Executive & Strategy'!W10:W69,"Yes")
B27: Total | C27: =SUM(C12:C26) | D27: =SUM(D12:D26) | E27: =SUM(E12:E26) | F27: =SUM(F12:F26) | G27: =SUM(G12:G26) | H27: =SUM(H12:H26) | I27: =SUM(I12:I26) | J27: =SUM(J12:J26)
B30: Chart title
B31: Internal hours by function

Sheet Decisions
B1: Decisions and assumptions
B4: Decisions that change scope, sequencing or risk. Keep them here so every function plans against the same assumptions.
B6: Decision or assumption | C6: Why it changes scope | D6: Current assumption or options | E6: Status | F6: Decision owner | G6: Target date | H6: Impact if delayed | I6: Notes
B7: Platform and hosting choice | C7: Sets the build effort, integrations and vendor contracts. | D7: Shortlist of two platforms | E7: In review | H7: High
B8: Cutover approach | C8: Big-bang or phased changes the peak workload and the risk. | D8: Phased by region | E8: Open | H8: High
B9: URL structure | C9: Drives redirects, search ranking and every link in other systems. | D9: Keep current paths where possible | E9: Open | H9: Critical
B10: Content freeze window | C10: Sets how long authors stop publishing before cutover. | D10: Two weeks | E10: Open | H10: Medium
B11: Legacy content treatment | C11: Decides what is moved, archived or retired. | D11: Move the last three years | E11: Open | H11: Medium
B12: Customer notification threshold | C12: Which changes need advance notice, and how much. | D12: 30 days for anything customers configure | E12: Open | H12: High

Sheet Dependencies
B1: Critical dependencies and risks
B4: Items most likely to set the critical path, or that need customers or third parties to act.
B6: Dependency or risk | C6: Lead function | D6: Supporting functions | E6: Why it's critical | F6: Customer action? | G6: External approval? | H6: Minimum lead time (days) | I6: Old and new side by side? | J6: Decision or mitigation | K6: Owner | L6: Status | M6: Target date | N6: Notes
B7: DNS and certificates for new hosts | C7: IT & Security | D7: Engineering; Marketing | E7: Nothing goes live without them. | F7: No | G7: No | H7: 14 | I7: Yes | J7: Order certificates as soon as hosts are named. | L7: Scoping
B8: Customer allowlist updates | C8: IT & Security | D8: Customer Success; Engineering | E8: Customers' firewalls may block the new hosts. | F8: Yes | G8: No | H8: 45 | I8: Yes | J8: Publish host list 45 days ahead. | L8: Scoping
B9: Single sign-on changes | C9: Engineering | D9: IT & Security; Customer Success | E9: Customers on SSO lose access if this is missed. | F9: Yes | G9: No | H9: 30 | I9: Yes | L9: Scoping
B10: Privacy notice update | C10: Legal & Privacy | D10: Marketing | E10: Must be live before the new site collects data. | F10: No | G10: Yes | H10: 21 | I10: No | L10: Scoping
B11: Marketplace listing changes | C11: Partners | D11: Marketing; Product | E11: Third-party review cycles are outside our control. | F11: No | G11: Yes | H11: 30 | I11: Unknown | L11: Scoping
B12: Payment portal move | C12: Finance & Procurement | D12: Engineering | E12: Billing must not be interrupted. | F12: Yes | G12: Yes | H12: 60 | I12: Yes | L12: Scoping

Sheet Marketing
B1: Marketing · scope
B4: Every asset, system and deliverable this function owns that the program touches. Blue text on white is yours to fill in. Light-blue cells calculate; leave them as they are.
B6: Replace the example rows, add what's missing, and mark rows Not applicable instead of deleting them.
B8: The item | G8: Volume | K8: Change | M8: Effort | R8: Cost | V8: Readiness | AB8: Risk | AE8: Plan
B9: Asset category | C9: Asset or deliverable | D9: Description or example | E9: Owner | F9: System or location | G9: Total quantity | H9: Active quantity | I9: % needing change | J9: Items to update | K9: Change type | L9: Complexity | M9: One-time setup hours | N9: Avg hours per item | O9: QA and review hours | P9: Total internal hours | Q9: Internal FTE days | R9: Blended hourly rate | S9: Internal cost | T9: External or vendor cost | U9: Total estimated cost | V9: Can bulk update or automate? | W9: Customer action needed? | X9: External notice needed? | Y9: External approval needed? | Z9: Dependency or prerequisite | AA9: Lead time (calendar days) | AB9: Business risk if missed | AC9: Customer disruption | AD9: Old and new run side by side? | AE9: Disposition | AF9: Required timing | AG9: Status | AH9: Notes and assumptions
B10: Website | C10: Web pages | D10: Corporate site pages moving to the new platform | E10: Web manager | F10: Current CMS | G10: 12 | H10: 12 | I10: 0.25 | J10: =IF(OR(H10="",I10=""),"",ROUND(H10*I10,0)) | K10: Content update | L10: Medium | M10: 24 | N10: 0.5 | O10: 16 | P10: =IF(AND(J10="",M10="",O10=""),"",N(M10)+N(J10)*N(N10)+N(O10)) | Q10: =IF(P10="","",P10/Lists!$C$18) | R10: 85 | S10: =IF(OR(P10="",R10=""),"",P10*R10) | T10: 5000 | U10: =IF(AND(S10="",T10=""),"",N(S10)+N(T10)) | V10: No | W10: No | X10: No | Y10: No | Z10: Platform choice confirmed | AA10: 45 | AB10: Low | AC10: Medium | AD10: No | AE10: Update | AF10: 0–30 days | AG10: Scoping | AH10: Example row: replace with your own estimate.
B11: Website | C11: URL redirects | D11: Map old URLs to new ones to keep traffic and search ranking | E11: Web manager | F11: Web host | G11: 250 | H11: 188 | I11: 0.5 | J11: =IF(OR(H11="",I11=""),"",ROUND(H11*I11,0)) | K11: Full rebuild | L11: Medium | M11: 16 | N11: 0.5 | O11: 16 | P11: =IF(AND(J11="",M11="",O11=""),"",N(M11)+N(J11)*N(N11)+N(O11)) | Q11: =IF(P11="","",P11/Lists!$C$18) | R11: 95 | S11: =IF(OR(P11="",R11=""),"",P11*R11) | T11: 12000 | U11: =IF(AND(S11="",T11=""),"",N(S11)+N(T11)) | V11: No | W11: No | X11: No | Y11: No | AA11: 14 | AB11: Critical | AC11: Low | AD11: Yes | AE11: Update | AF11: 0–30 days | AG11: Validated
B12: Website | C12: Web forms | D12: Contact, demo and download forms | E12: Marketing operations | F12: Marketing automation | G12: 60 | H12: 36 | I12: 0.75 | J12: =IF(OR(H12="",I12=""),"",ROUND(H12*I12,0)) | K12: Multiple changes | L12: High | M12: 24 | N12: 4 | O12: 2 | P12: =IF(AND(J12="",M12="",O12=""),"",N(M12)+N(J12)*N(N12)+N(O12)) | Q12: =IF(P12="","",P12/Lists!$C$18) | R12: 85 | S12: =IF(OR(P12="",R12=""),"",P12*R12) | T12: 5000 | U12: =IF(AND(S12="",T12=""),"",N(S12)+N(T12)) | V12: Yes | W12: Yes | X12: Partial | Y12: Yes | AA12: 30 | AB12: Medium | AC12: Medium | AD12: Yes | AE12: Update | AF12: 0–30 days | AG12: Not started
B13: Email | C13: Email templates | D13: Newsletter and nurture templates that link to the site | E13: Marketing operations | F13: Marketing automation | G13: 4 | H13: 2 | I13: 0.5 | J13: =IF(OR(H13="",I13=""),"",ROUND(H13*I13,0)) | K13: URL / link | L13: High | M13: 4 | N13: 0.5 | O13: 2 | P13: =IF(AND(J13="",M13="",O13=""),"",N(M13)+N(J13)*N(N13)+N(O13)) | Q13: =IF(P13="","",P13/Lists!$C$18) | R13: 85 | S13: =IF(OR(P13="",R13=""),"",P13*R13) | T13: 5000 | U13: =IF(AND(S13="",T13=""),"",N(S13)+N(T13)) | V13: No | W13: No | X13: Partial | Y13: No | AA13: 30 | AB13: Medium | AC13: High | AD13: No | AE13: Update | AF13: 31–90 days | AG13: Scoping
B14: Content | C14: Resource library | D14: Guides, reports and case studies with site links | E14: Content lead | F14: Current CMS | G14: 40 | H14: 24 | I14: 1 | J14: =IF(OR(H14="",I14=""),"",ROUND(H14*I14,0)) | K14: Full rebuild | L14: Medium | M14: 40 | N14: 4 | O14: 4 | P14: =IF(AND(J14="",M14="",O14=""),"",N(M14)+N(J14)*N(N14)+N(O14)) | Q14: =IF(P14="","",P14/Lists!$C$18) | R14: 85 | S14: =IF(OR(P14="",R14=""),"",P14*R14) | T14: 5000 | U14: =IF(AND(S14="",T14=""),"",N(S14)+N(T14)) | V14: No | W14: Yes | X14: Yes | Y14: No | AA14: 30 | AB14: High | AC14: Medium | AD14: Partial | AE14: Redirect | AF14: 31–90 days | AG14: Scoping
B15: Social | C15: Social profile links | D15: Profile and bio links across social channels | E15: Social lead | F15: Social platforms | G15: 60 | H15: 60 | I15: 0.75 | J15: =IF(OR(H15="",I15=""),"",ROUND(H15*I15,0)) | K15: URL / link | L15: Medium | M15: 40 | N15: 4 | O15: 16 | P15: =IF(AND(J15="",M15="",O15=""),"",N(M15)+N(J15)*N(N15)+N(O15)) | Q15: =IF(P15="","",P15/Lists!$C$18) | S15: =IF(OR(P15="",R15=""),"",P15*R15) | T15: 30000 | U15: =IF(AND(S15="",T15=""),"",N(S15)+N(T15)) | V15: Yes | W15: No | X15: Partial | Y15: Yes | AA15: 60 | AB15: Medium | AC15: Medium | AD15: Yes | AE15: Merge | AF15: 0–30 days | AG15: Scoping
J16: =IF(OR(H16="",I16=""),"",ROUND(H16*I16,0)) | P16: =IF(AND(J16="",M16="",O16=""),"",N(M16)+N(J16)*N(N16)+N(O16)) | Q16: =IF(P16="","",P16/Lists!$C$18) | S16: =IF(OR(P16="",R16=""),"",P16*R16) | U16: =IF(AND(S16="",T16=""),"",N(S16)+N(T16))
J17: =IF(OR(H17="",I17=""),"",ROUND(H17*I17,0)) | P17: =IF(AND(J17="",M17="",O17=""),"",N(M17)+N(J17)*N(N17)+N(O17)) | Q17: =IF(P17="","",P17/Lists!$C$18) | S17: =IF(OR(P17="",R17=""),"",P17*R17) | U17: =IF(AND(S17="",T17=""),"",N(S17)+N(T17))
J18: =IF(OR(H18="",I18=""),"",ROUND(H18*I18,0)) | P18: =IF(AND(J18="",M18="",O18=""),"",N(M18)+N(J18)*N(N18)+N(O18)) | Q18: =IF(P18="","",P18/Lists!$C$18) | S18: =IF(OR(P18="",R18=""),"",P18*R18) | U18: =IF(AND(S18="",T18=""),"",N(S18)+N(T18))
J19: =IF(OR(H19="",I19=""),"",ROUND(H19*I19,0)) | P19: =IF(AND(J19="",M19="",O19=""),"",N(M19)+N(J19)*N(N19)+N(O19)) | Q19: =IF(P19="","",P19/Lists!$C$18) | S19: =IF(OR(P19="",R19=""),"",P19*R19) | U19: =IF(AND(S19="",T19=""),"",N(S19)+N(T19))
J20: =IF(OR(H20="",I20=""),"",ROUND(H20*I20,0)) | P20: =IF(AND(J20="",M20="",O20=""),"",N(M20)+N(J20)*N(N20)+N(O20)) | Q20: =IF(P20="","",P20/Lists!$C$18) | S20: =IF(OR(P20="",R20=""),"",P20*R20) | U20: =IF(AND(S20="",T20=""),"",N(S20)+N(T20))
J21: =IF(OR(H21="",I21=""),"",ROUND(H21*I21,0)) | P21: =IF(AND(J21="",M21="",O21=""),"",N(M21)+N(J21)*N(N21)+N(O21)) | Q21: =IF(P21="","",P21/Lists!$C$18) | S21: =IF(OR(P21="",R21=""),"",P21*R21) | U21: =IF(AND(S21="",T21=""),"",N(S21)+N(T21))
J22: =IF(OR(H22="",I22=""),"",ROUND(H22*I22,0)) | P22: =IF(AND(J22="",M22="",O22=""),"",N(M22)+N(J22)*N(N22)+N(O22)) | Q22: =IF(P22="","",P22/Lists!$C$18) | S22: =IF(OR(P22="",R22=""),"",P22*R22) | U22: =IF(AND(S22="",T22=""),"",N(S22)+N(T22))
J23: =IF(OR(H23="",I23=""),"",ROUND(H23*I23,0)) | P23: =IF(AND(J23="",M23="",O23=""),"",N(M23)+N(J23)*N(N23)+N(O23)) | Q23: =IF(P23="","",P23/Lists!$C$18) | S23: =IF(OR(P23="",R23=""),"",P23*R23) | U23: =IF(AND(S23="",T23=""),"",N(S23)+N(T23))
J24: =IF(OR(H24="",I24=""),"",ROUND(H24*I24,0)) | P24: =IF(AND(J24="",M24="",O24=""),"",N(M24)+N(J24)*N(N24)+N(O24)) | Q24: =IF(P24="","",P24/Lists!$C$18) | S24: =IF(OR(P24="",R24=""),"",P24*R24) | U24: =IF(AND(S24="",T24=""),"",N(S24)+N(T24))
J25: =IF(OR(H25="",I25=""),"",ROUND(H25*I25,0)) | P25: =IF(AND(J25="",M25="",O25=""),"",N(M25)+N(J25)*N(N25)+N(O25)) | Q25: =IF(P25="","",P25/Lists!$C$18) | S25: =IF(OR(P25="",R25=""),"",P25*R25) | U25: =IF(AND(S25="",T25=""),"",N(S25)+N(T25))
J26: =IF(OR(H26="",I26=""),"",ROUND(H26*I26,0)) | P26: =IF(AND(J26="",M26="",O26=""),"",N(M26)+N(J26)*N(N26)+N(O26)) | Q26: =IF(P26="","",P26/Lists!$C$18) | S26: =IF(OR(P26="",R26=""),"",P26*R26) | U26: =IF(AND(S26="",T26=""),"",N(S26)+N(T26))
J27: =IF(OR(H27="",I27=""),"",ROUND(H27*I27,0)) | P27: =IF(AND(J27="",M27="",O27=""),"",N(M27)+N(J27)*N(N27)+N(O27)) | Q27: =IF(P27="","",P27/Lists!$C$18) | S27: =IF(OR(P27="",R27=""),"",P27*R27) | U27: =IF(AND(S27="",T27=""),"",N(S27)+N(T27))
... J69: =IF(OR(H69="",I69=""),"",ROUND(H69*I69,0)) | P69: =IF(AND(J69="",M69="",O69=""),"",N(M69)+N(J69)*N(N69)+N(O69)) | Q69: =IF(P69="","",P69/Lists!$C$18) | S69: =IF(OR(P69="",R69=""),"",P69*R69) | U69: =IF(AND(S69="",T69=""),"",N(S69)+N(T69))
B70: Marketing total | G70: =SUM(G10:G69) | H70: =SUM(H10:H69) | J70: =SUM(J10:J69) | M70: =SUM(M10:M69) | O70: =SUM(O10:O69) | P70: =SUM(P10:P69) | Q70: =SUM(Q10:Q69) | S70: =SUM(S10:S69) | T70: =SUM(T10:T69) | U70: =SUM(U10:U69)

Sheet Product
B1: Product · scope
B4: Every asset, system and deliverable this function owns that the program touches. Blue text on white is yours to fill in. Light-blue cells calculate; leave them as they are.
B6: Replace the example rows, add what's missing, and mark rows Not applicable instead of deleting them.
B8: The item | G8: Volume | K8: Change | M8: Effort | R8: Cost | V8: Readiness | AB8: Risk | AE8: Plan
B9: Asset category | C9: Asset or deliverable | D9: Description or example | E9: Owner | F9: System or location | G9: Total quantity | H9: Active quantity | I9: % needing change | J9: Items to update | K9: Change type | L9: Complexity | M9: One-time setup hours | N9: Avg hours per item | O9: QA and review hours | P9: Total internal hours | Q9: Internal FTE days | R9: Blended hourly rate | S9: Internal cost | T9: External or vendor cost | U9: Total estimated cost | V9: Can bulk update or automate? | W9: Customer action needed? | X9: External notice needed? | Y9: External approval needed? | Z9: Dependency or prerequisite | AA9: Lead time (calendar days) | AB9: Business risk if missed | AC9: Customer disruption | AD9: Old and new run side by side? | AE9: Disposition | AF9: Required timing | AG9: Status | AH9: Notes and assumptions
B10: In-product | C10: Help links | D10: Links from the product UI to help articles | E10: Product manager | F10: Product codebase | G10: 60 | H10: 54 | I10: 0.5 | J10: =IF(OR(H10="",I10=""),"",ROUND(H10*I10,0)) | K10: Technical configuration | L10: High | M10: 16 | N10: 1 | O10: 8 | P10: =IF(AND(J10="",M10="",O10=""),"",N(M10)+N(J10)*N(N10)+N(O10)) | Q10: =IF(P10="","",P10/Lists!$C$18) | R10: 85 | S10: =IF(OR(P10="",R10=""),"",P10*R10) | U10: =IF(AND(S10="",T10=""),"",N(S10)+N(T10)) | V10: Yes | W10: No | X10: No | Y10: No | Z10: Platform choice confirmed | AA10: 5 | AB10: Low | AC10: High | AD10: Yes | AE10: Update | AF10: Before cutover | AG10: Validated | AH10: Example row: replace with your own estimate.
B11: Documentation | C11: Release notes | D11: Published notes that reference portal pages | E11: Product marketing | F11: Docs site | G11: 40 | H11: 36 | I11: 0.75 | J11: =IF(OR(H11="",I11=""),"",ROUND(H11*I11,0)) | K11: Technical configuration | L11: High | M11: 4 | N11: 0.25 | O11: 16 | P11: =IF(AND(J11="",M11="",O11=""),"",N(M11)+N(J11)*N(N11)+N(O11)) | Q11: =IF(P11="","",P11/Lists!$C$18) | R11: 95 | S11: =IF(OR(P11="",R11=""),"",P11*R11) | U11: =IF(AND(S11="",T11=""),"",N(S11)+N(T11)) | V11: No | W11: No | X11: No | Y11: No | AA11: 10 | AB11: Medium | AC11: Low | AD11: Partial | AE11: Update | AF11: 0–30 days | AG11: Validated
B12: In-product | C12: Notification emails | D12: System emails sent from the product | E12: Product manager | F12: Notification service | G12: 250 | H12: 188 | I12: 0.25 | J12: =IF(OR(H12="",I12=""),"",ROUND(H12*I12,0)) | K12: Visual update | L12: Low | M12: 40 | N12: 2 | O12: 8 | P12: =IF(AND(J12="",M12="",O12=""),"",N(M12)+N(J12)*N(N12)+N(O12)) | Q12: =IF(P12="","",P12/Lists!$C$18) | R12: 85 | S12: =IF(OR(P12="",R12=""),"",P12*R12) | U12: =IF(AND(S12="",T12=""),"",N(S12)+N(T12)) | V12: No | W12: Yes | X12: No | Y12: No | AA12: 10 | AB12: Medium | AC12: Low | AD12: No | AE12: Update | AF12: Before cutover | AG12: Scoping
B13: Documentation | C13: Admin guides | D13: Online and PDF admin guides | E13: Technical writer | F13: Docs site | G13: 800 | H13: 600 | I13: 0.5 | J13: =IF(OR(H13="",I13=""),"",ROUND(H13*I13,0)) | K13: Legal text | L13: Low | M13: 24 | N13: 0.5 | O13: 2 | P13: =IF(AND(J13="",M13="",O13=""),"",N(M13)+N(J13)*N(N13)+N(O13)) | Q13: =IF(P13="","",P13/Lists!$C$18) | R13: 95 | S13: =IF(OR(P13="",R13=""),"",P13*R13) | U13: =IF(AND(S13="",T13=""),"",N(S13)+N(T13)) | V13: No | W13: No | X13: Partial | Y13: Yes | AA13: 60 | AB13: Low | AC13: Medium | AD13: Partial | AE13: Retire | AF13: 0–30 days | AG13: Not started
J14: =IF(OR(H14="",I14=""),"",ROUND(H14*I14,0)) | P14: =IF(AND(J14="",M14="",O14=""),"",N(M14)+N(J14)*N(N14)+N(O14)) | Q14: =IF(P14="","",P14/Lists!$C$18) | S14: =IF(OR(P14="",R14=""),"",P14*R14) | U14: =IF(AND(S14="",T14=""),"",N(S14)+N(T14))
J15: =IF(OR(H15="",I15=""),"",ROUND(H15*I15,0)) | P15: =IF(AND(J15="",M15="",O15=""),"",N(M15)+N(J15)*N(N15)+N(O15)) | Q15: =IF(P15="","",P15/Lists!$C$18) | S15: =IF(OR(P15="",R15=""),"",P15*R15) | U15: =IF(AND(S15="",T15=""),"",N(S15)+N(T15))
J16: =IF(OR(H16="",I16=""),"",ROUND(H16*I16,0)) | P16: =IF(AND(J16="",M16="",O16=""),"",N(M16)+N(J16)*N(N16)+N(O16)) | Q16: =IF(P16="","",P16/Lists!$C$18) | S16: =IF(OR(P16="",R16=""),"",P16*R16) | U16: =IF(AND(S16="",T16=""),"",N(S16)+N(T16))
J17: =IF(OR(H17="",I17=""),"",ROUND(H17*I17,0)) | P17: =IF(AND(J17="",M17="",O17=""),"",N(M17)+N(J17)*N(N17)+N(O17)) | Q17: =IF(P17="","",P17/Lists!$C$18) | S17: =IF(OR(P17="",R17=""),"",P17*R17) | U17: =IF(AND(S17="",T17=""),"",N(S17)+N(T17))
J18: =IF(OR(H18="",I18=""),"",ROUND(H18*I18,0)) | P18: =IF(AND(J18="",M18="",O18=""),"",N(M18)+N(J18)*N(N18)+N(O18)) | Q18: =IF(P18="","",P18/Lists!$C$18) | S18: =IF(OR(P18="",R18=""),"",P18*R18) | U18: =IF(AND(S18="",T18=""),"",N(S18)+N(T18))
J19: =IF(OR(H19="",I19=""),"",ROUND(H19*I19,0)) | P19: =IF(AND(J19="",M19="",O19=""),"",N(M19)+N(J19)*N(N19)+N(O19)) | Q19: =IF(P19="","",P19/Lists!$C$18) | S19: =IF(OR(P19="",R19=""),"",P19*R19) | U19: =IF(AND(S19="",T19=""),"",N(S19)+N(T19))
J20: =IF(OR(H20="",I20=""),"",ROUND(H20*I20,0)) | P20: =IF(AND(J20="",M20="",O20=""),"",N(M20)+N(J20)*N(N20)+N(O20)) | Q20: =IF(P20="","",P20/Lists!$C$18) | S20: =IF(OR(P20="",R20=""),"",P20*R20) | U20: =IF(AND(S20="",T20=""),"",N(S20)+N(T20))
J21: =IF(OR(H21="",I21=""),"",ROUND(H21*I21,0)) | P21: =IF(AND(J21="",M21="",O21=""),"",N(M21)+N(J21)*N(N21)+N(O21)) | Q21: =IF(P21="","",P21/Lists!$C$18) | S21: =IF(OR(P21="",R21=""),"",P21*R21) | U21: =IF(AND(S21="",T21=""),"",N(S21)+N(T21))
J22: =IF(OR(H22="",I22=""),"",ROUND(H22*I22,0)) | P22: =IF(AND(J22="",M22="",O22=""),"",N(M22)+N(J22)*N(N22)+N(O22)) | Q22: =IF(P22="","",P22/Lists!$C$18) | S22: =IF(OR(P22="",R22=""),"",P22*R22) | U22: =IF(AND(S22="",T22=""),"",N(S22)+N(T22))
J23: =IF(OR(H23="",I23=""),"",ROUND(H23*I23,0)) | P23: =IF(AND(J23="",M23="",O23=""),"",N(M23)+N(J23)*N(N23)+N(O23)) | Q23: =IF(P23="","",P23/Lists!$C$18) | S23: =IF(OR(P23="",R23=""),"",P23*R23) | U23: =IF(AND(S23="",T23=""),"",N(S23)+N(T23))
J24: =IF(OR(H24="",I24=""),"",ROUND(H24*I24,0)) | P24: =IF(AND(J24="",M24="",O24=""),"",N(M24)+N(J24)*N(N24)+N(O24)) | Q24: =IF(P24="","",P24/Lists!$C$18) | S24: =IF(OR(P24="",R24=""),"",P24*R24) | U24: =IF(AND(S24="",T24=""),"",N(S24)+N(T24))
J25: =IF(OR(H25="",I25=""),"",ROUND(H25*I25,0)) | P25: =IF(AND(J25="",M25="",O25=""),"",N(M25)+N(J25)*N(N25)+N(O25)) | Q25: =IF(P25="","",P25/Lists!$C$18) | S25: =IF(OR(P25="",R25=""),"",P25*R25) | U25: =IF(AND(S25="",T25=""),"",N(S25)+N(T25))
... J69: =IF(OR(H69="",I69=""),"",ROUND(H69*I69,0)) | P69: =IF(AND(J69="",M69="",O69=""),"",N(M69)+N(J69)*N(N69)+N(O69)) | Q69: =IF(P69="","",P69/Lists!$C$18) | S69: =IF(OR(P69="",R69=""),"",P69*R69) | U69: =IF(AND(S69="",T69=""),"",N(S69)+N(T69))
B70: Product total | G70: =SUM(G10:G69) | H70: =SUM(H10:H69) | J70: =SUM(J10:J69) | M70: =SUM(M10:M69) | O70: =SUM(O10:O69) | P70: =SUM(P10:P69) | Q70: =SUM(Q10:Q69) | S70: =SUM(S10:S69) | T70: =SUM(T10:T69) | U70: =SUM(U10:U69)

Sheet Engineering
B1: Engineering · scope
B4: Every asset, system and deliverable this function owns that the program touches. Blue text on white is yours to fill in. Light-blue cells calculate; leave them as they are.
B6: Replace the example rows, add what's missing, and mark rows Not applicable instead of deleting them.
B8: The item | G8: Volume | K8: Change | M8: Effort | R8: Cost | V8: Readiness | AB8: Risk | AE8: Plan
B9: Asset category | C9: Asset or deliverable | D9: Description or example | E9: Owner | F9: System or location | G9: Total quantity | H9: Active quantity | I9: % needing change | J9: Items to update | K9: Change type | L9: Complexity | M9: One-time setup hours | N9: Avg hours per item | O9: QA and review hours | P9: Total internal hours | Q9: Internal FTE days | R9: Blended hourly rate | S9: Internal cost | T9: External or vendor cost | U9: Total estimated cost | V9: Can bulk update or automate? | W9: Customer action needed? | X9: External notice needed? | Y9: External approval needed? | Z9: Dependency or prerequisite | AA9: Lead time (calendar days) | AB9: Business risk if missed | AC9: Customer disruption | AD9: Old and new run side by side? | AE9: Disposition | AF9: Required timing | AG9: Status | AH9: Notes and assumptions
B10: Integrations | C10: API documentation | D10: Endpoint references and code samples | E10: Engineering lead | F10: Developer portal | G10: 40 | H10: 30 | I10: 1 | J10: =IF(OR(H10="",I10=""),"",ROUND(H10*I10,0)) | K10: Multiple changes | L10: Low | M10: 8 | N10: 2 | O10: 8 | P10: =IF(AND(J10="",M10="",O10=""),"",N(M10)+N(J10)*N(N10)+N(O10)) | Q10: =IF(P10="","",P10/Lists!$C$18) | R10: 95 | S10: =IF(OR(P10="",R10=""),"",P10*R10) | U10: =IF(AND(S10="",T10=""),"",N(S10)+N(T10)) | V10: No | W10: No | X10: No | Y10: No | Z10: Platform choice confirmed | AA10: 45 | AB10: Medium | AC10: Medium | AD10: Yes | AE10: Redirect | AF10: Before cutover | AG10: Validated | AH10: Example row: replace with your own estimate.
B11: Integrations | C11: Webhook endpoints | D11: Callback URLs that customers configure | E11: Engineering lead | F11: Platform | G11: 25 | H11: 22 | I11: 0.75 | J11: =IF(OR(H11="",I11=""),"",ROUND(H11*I11,0)) | K11: Legal text | L11: High | M11: 16 | N11: 0.5 | O11: 4 | P11: =IF(AND(J11="",M11="",O11=""),"",N(M11)+N(J11)*N(N11)+N(O11)) | Q11: =IF(P11="","",P11/Lists!$C$18) | R11: 85 | S11: =IF(OR(P11="",R11=""),"",P11*R11) | U11: =IF(AND(S11="",T11=""),"",N(S11)+N(T11)) | V11: Yes | W11: Yes | X11: No | Y11: No | AA11: 60 | AB11: Critical | AC11: Critical | AD11: Partial | AE11: Update | AF11: Cutover day | AG11: Scoping
B12: Authentication | C12: Single sign-on settings | D12: Identity provider setup for the portal | E12: Platform engineer | F12: Identity provider | G12: 800 | H12: 600 | I12: 1 | J12: =IF(OR(H12="",I12=""),"",ROUND(H12*I12,0)) | K12: URL / link | L12: Critical | M12: 8 | N12: 1 | O12: 4 | P12: =IF(AND(J12="",M12="",O12=""),"",N(M12)+N(J12)*N(N12)+N(O12)) | Q12: =IF(P12="","",P12/Lists!$C$18) | R12: 95 | S12: =IF(OR(P12="",R12=""),"",P12*R12) | T12: 12000 | U12: =IF(AND(S12="",T12=""),"",N(S12)+N(T12)) | V12: No | W12: Yes | X12: Yes | Y12: No | AA12: 14 | AB12: High | AC12: High | AD12: No | AE12: Update | AF12: 0–30 days | AG12: Scoping
B13: Infrastructure | C13: Monitoring checks | D13: Uptime and synthetic checks on portal pages | E13: SRE lead | F13: Monitoring tool | G13: 250 | H13: 188 | I13: 1 | J13: =IF(OR(H13="",I13=""),"",ROUND(H13*I13,0)) | K13: Full rebuild | L13: High | M13: 16 | N13: 2 | O13: 16 | P13: =IF(AND(J13="",M13="",O13=""),"",N(M13)+N(J13)*N(N13)+N(O13)) | Q13: =IF(P13="","",P13/Lists!$C$18) | R13: 95 | S13: =IF(OR(P13="",R13=""),"",P13*R13) | T13: 5000 | U13: =IF(AND(S13="",T13=""),"",N(S13)+N(T13)) | V13: No | W13: Yes | X13: Yes | Y13: Yes | AA13: 5 | AB13: Low | AC13: High | AD13: No | AE13: Update | AF13: Cutover day | AG13: Validated
J14: =IF(OR(H14="",I14=""),"",ROUND(H14*I14,0)) | P14: =IF(AND(J14="",M14="",O14=""),"",N(M14)+N(J14)*N(N14)+N(O14)) | Q14: =IF(P14="","",P14/Lists!$C$18) | S14: =IF(OR(P14="",R14=""),"",P14*R14) | U14: =IF(AND(S14="",T14=""),"",N(S14)+N(T14))
J15: =IF(OR(H15="",I15=""),"",ROUND(H15*I15,0)) | P15: =IF(AND(J15="",M15="",O15=""),"",N(M15)+N(J15)*N(N15)+N(O15)) | Q15: =IF(P15="","",P15/Lists!$C$18) | S15: =IF(OR(P15="",R15=""),"",P15*R15) | U15: =IF(AND(S15="",T15=""),"",N(S15)+N(T15))
J16: =IF(OR(H16="",I16=""),"",ROUND(H16*I16,0)) | P16: =IF(AND(J16="",M16="",O16=""),"",N(M16)+N(J16)*N(N16)+N(O16)) | Q16: =IF(P16="","",P16/Lists!$C$18) | S16: =IF(OR(P16="",R16=""),"",P16*R16) | U16: =IF(AND(S16="",T16=""),"",N(S16)+N(T16))
J17: =IF(OR(H17="",I17=""),"",ROUND(H17*I17,0)) | P17: =IF(AND(J17="",M17="",O17=""),"",N(M17)+N(J17)*N(N17)+N(O17)) | Q17: =IF(P17="","",P17/Lists!$C$18) | S17: =IF(OR(P17="",R17=""),"",P17*R17) | U17: =IF(AND(S17="",T17=""),"",N(S17)+N(T17))
J18: =IF(OR(H18="",I18=""),"",ROUND(H18*I18,0)) | P18: =IF(AND(J18="",M18="",O18=""),"",N(M18)+N(J18)*N(N18)+N(O18)) | Q18: =IF(P18="","",P18/Lists!$C$18) | S18: =IF(OR(P18="",R18=""),"",P18*R18) | U18: =IF(AND(S18="",T18=""),"",N(S18)+N(T18))
J19: =IF(OR(H19="",I19=""),"",ROUND(H19*I19,0)) | P19: =IF(AND(J19="",M19="",O19=""),"",N(M19)+N(J19)*N(N19)+N(O19)) | Q19: =IF(P19="","",P19/Lists!$C$18) | S19: =IF(OR(P19="",R19=""),"",P19*R19) | U19: =IF(AND(S19="",T19=""),"",N(S19)+N(T19))
J20: =IF(OR(H20="",I20=""),"",ROUND(H20*I20,0)) | P20: =IF(AND(J20="",M20="",O20=""),"",N(M20)+N(J20)*N(N20)+N(O20)) | Q20: =IF(P20="","",P20/Lists!$C$18) | S20: =IF(OR(P20="",R20=""),"",P20*R20) | U20: =IF(AND(S20="",T20=""),"",N(S20)+N(T20))
J21: =IF(OR(H21="",I21=""),"",ROUND(H21*I21,0)) | P21: =IF(AND(J21="",M21="",O21=""),"",N(M21)+N(J21)*N(N21)+N(O21)) | Q21: =IF(P21="","",P21/Lists!$C$18) | S21: =IF(OR(P21="",R21=""),"",P21*R21) | U21: =IF(AND(S21="",T21=""),"",N(S21)+N(T21))
J22: =IF(OR(H22="",I22=""),"",ROUND(H22*I22,0)) | P22: =IF(AND(J22="",M22="",O22=""),"",N(M22)+N(J22)*N(N22)+N(O22)) | Q22: =IF(P22="","",P22/Lists!$C$18) | S22: =IF(OR(P22="",R22=""),"",P22*R22) | U22: =IF(AND(S22="",T22=""),"",N(S22)+N(T22))
J23: =IF(OR(H23="",I23=""),"",ROUND(H23*I23,0)) | P23: =IF(AND(J23="",M23="",O23=""),"",N(M23)+N(J23)*N(N23)+N(O23)) | Q23: =IF(P23="","",P23/Lists!$C$18) | S23: =IF(OR(P23="",R23=""),"",P23*R23) | U23: =IF(AND(S23="",T23=""),"",N(S23)+N(T23))
J24: =IF(OR(H24="",I24=""),"",ROUND(H24*I24,0)) | P24: =IF(AND(J24="",M24="",O24=""),"",N(M24)+N(J24)*N(N24)+N(O24)) | Q24: =IF(P24="","",P24/Lists!$C$18) | S24: =IF(OR(P24="",R24=""),"",P24*R24) | U24: =IF(AND(S24="",T24=""),"",N(S24)+N(T24))
J25: =IF(OR(H25="",I25=""),"",ROUND(H25*I25,0)) | P25: =IF(AND(J25="",M25="",O25=""),"",N(M25)+N(J25)*N(N25)+N(O25)) | Q25: =IF(P25="","",P25/Lists!$C$18) | S25: =IF(OR(P25="",R25=""),"",P25*R25) | U25: =IF(AND(S25="",T25=""),"",N(S25)+N(T25))
... J69: =IF(OR(H69="",I69=""),"",ROUND(H69*I69,0)) | P69: =IF(AND(J69="",M69="",O69=""),"",N(M69)+N(J69)*N(N69)+N(O69)) | Q69: =IF(P69="","",P69/Lists!$C$18) | S69: =IF(OR(P69="",R69=""),"",P69*R69) | U69: =IF(AND(S69="",T69=""),"",N(S69)+N(T69))
B70: Engineering total | G70: =SUM(G10:G69) | H70: =SUM(H10:H69) | J70: =SUM(J10:J69) | M70: =SUM(M10:M69) | O70: =SUM(O10:O69) | P70: =SUM(P10:P69) | Q70: =SUM(Q10:Q69) | S70: =SUM(S10:S69) | T70: =SUM(T10:T69) | U70: =SUM(U10:U69)

Sheet IT & Security
B1: IT & Security · scope
B4: Every asset, system and deliverable this function owns that the program touches. Blue text on white is yours to fill in. Light-blue cells calculate; leave them as they are.
B6: Replace the example rows, add what's missing, and mark rows Not applicable instead of deleting them.
B8: The item | G8: Volume | K8: Change | M8: Effort | R8: Cost | V8: Readiness | AB8: Risk | AE8: Plan
B9: Asset category | C9: Asset or deliverable | D9: Description or example | E9: Owner | F9: System or location | G9: Total quantity | H9: Active quantity | I9: % needing change | J9: Items to update | K9: Change type | L9: Complexity | M9: One-time setup hours | N9: Avg hours per item | O9: QA and review hours | P9: Total internal hours | Q9: Internal FTE days | R9: Blended hourly rate | S9: Internal cost | T9: External or vendor cost | U9: Total estimated cost | V9: Can bulk update or automate? | W9: Customer action needed? | X9: External notice needed? | Y9: External approval needed? | Z9: Dependency or prerequisite | AA9: Lead time (calendar days) | AB9: Business risk if missed | AC9: Customer disruption | AD9: Old and new run side by side? | AE9: Disposition | AF9: Required timing | AG9: Status | AH9: Notes and assumptions
B10: Network | C10: DNS records | D10: Records for the new portal and site hosts | E10: IT lead | F10: DNS provider | G10: 800 | H10: 480 | I10: 0.25 | J10: =IF(OR(H10="",I10=""),"",ROUND(H10*I10,0)) | K10: Technical configuration | L10: Medium | M10: 16 | N10: 4 | O10: 8 | P10: =IF(AND(J10="",M10="",O10=""),"",N(M10)+N(J10)*N(N10)+N(O10)) | Q10: =IF(P10="","",P10/Lists!$C$18) | R10: 95 | S10: =IF(OR(P10="",R10=""),"",P10*R10) | T10: 5000 | U10: =IF(AND(S10="",T10=""),"",N(S10)+N(T10)) | V10: No | W10: No | X10: Yes | Y10: No | Z10: Platform choice confirmed | AA10: 45 | AB10: Critical | AC10: High | AD10: No | AE10: Merge | AF10: 31–90 days | AG10: Scoping | AH10: Example row: replace with your own estimate.
B11: Security | C11: TLS certificates | D11: Certificates for the new hosts | E11: Security engineer | F11: Certificate manager | G11: 4 | H11: 3 | I11: 1 | J11: =IF(OR(H11="",I11=""),"",ROUND(H11*I11,0)) | K11: URL / link | L11: Critical | M11: 4 | N11: 1 | O11: 2 | P11: =IF(AND(J11="",M11="",O11=""),"",N(M11)+N(J11)*N(N11)+N(O11)) | Q11: =IF(P11="","",P11/Lists!$C$18) | S11: =IF(OR(P11="",R11=""),"",P11*R11) | T11: 12000 | U11: =IF(AND(S11="",T11=""),"",N(S11)+N(T11)) | V11: No | W11: Yes | X11: Yes | Y11: No | AA11: 5 | AB11: Critical | AC11: Critical | AD11: Yes | AE11: Update | AF11: Cutover day | AG11: Validated
B12: Security | C12: Allowlists | D12: Firewall and proxy rules that name portal hosts | E12: Security engineer | F12: Firewall | G12: 12 | H12: 12 | I12: 0.25 | J12: =IF(OR(H12="",I12=""),"",ROUND(H12*I12,0)) | K12: URL / link | L12: Critical | M12: 4 | N12: 2 | O12: 2 | P12: =IF(AND(J12="",M12="",O12=""),"",N(M12)+N(J12)*N(N12)+N(O12)) | Q12: =IF(P12="","",P12/Lists!$C$18) | S12: =IF(OR(P12="",R12=""),"",P12*R12) | T12: 12000 | U12: =IF(AND(S12="",T12=""),"",N(S12)+N(T12)) | V12: No | W12: No | X12: Partial | Y12: No | AA12: 10 | AB12: High | AC12: Critical | AD12: Partial | AE12: Update | AF12: 31–90 days | AG12: Scoping
B13: Workplace | C13: Intranet links | D13: Intranet pages and bookmarks that point to the portal | E13: IT service desk | F13: Intranet | G13: 250 | H13: 150 | I13: 0.25 | J13: =IF(OR(H13="",I13=""),"",ROUND(H13*I13,0)) | K13: Legal text | L13: Critical | M13: 24 | N13: 4 | O13: 4 | P13: =IF(AND(J13="",M13="",O13=""),"",N(M13)+N(J13)*N(N13)+N(O13)) | Q13: =IF(P13="","",P13/Lists!$C$18) | S13: =IF(OR(P13="",R13=""),"",P13*R13) | T13: 12000 | U13: =IF(AND(S13="",T13=""),"",N(S13)+N(T13)) | V13: Partial | W13: No | X13: Partial | Y13: No | AA13: 14 | AB13: Medium | AC13: Low | AD13: Partial | AE13: Update | AF13: Cutover day | AG13: Scoping
J14: =IF(OR(H14="",I14=""),"",ROUND(H14*I14,0)) | P14: =IF(AND(J14="",M14="",O14=""),"",N(M14)+N(J14)*N(N14)+N(O14)) | Q14: =IF(P14="","",P14/Lists!$C$18) | S14: =IF(OR(P14="",R14=""),"",P14*R14) | U14: =IF(AND(S14="",T14=""),"",N(S14)+N(T14))
J15: =IF(OR(H15="",I15=""),"",ROUND(H15*I15,0)) | P15: =IF(AND(J15="",M15="",O15=""),"",N(M15)+N(J15)*N(N15)+N(O15)) | Q15: =IF(P15="","",P15/Lists!$C$18) | S15: =IF(OR(P15="",R15=""),"",P15*R15) | U15: =IF(AND(S15="",T15=""),"",N(S15)+N(T15))
J16: =IF(OR(H16="",I16=""),"",ROUND(H16*I16,0)) | P16: =IF(AND(J16="",M16="",O16=""),"",N(M16)+N(J16)*N(N16)+N(O16)) | Q16: =IF(P16="","",P16/Lists!$C$18) | S16: =IF(OR(P16="",R16=""),"",P16*R16) | U16: =IF(AND(S16="",T16=""),"",N(S16)+N(T16))
J17: =IF(OR(H17="",I17=""),"",ROUND(H17*I17,0)) | P17: =IF(AND(J17="",M17="",O17=""),"",N(M17)+N(J17)*N(N17)+N(O17)) | Q17: =IF(P17="","",P17/Lists!$C$18) | S17: =IF(OR(P17="",R17=""),"",P17*R17) | U17: =IF(AND(S17="",T17=""),"",N(S17)+N(T17))
J18: =IF(OR(H18="",I18=""),"",ROUND(H18*I18,0)) | P18: =IF(AND(J18="",M18="",O18=""),"",N(M18)+N(J18)*N(N18)+N(O18)) | Q18: =IF(P18="","",P18/Lists!$C$18) | S18: =IF(OR(P18="",R18=""),"",P18*R18) | U18: =IF(AND(S18="",T18=""),"",N(S18)+N(T18))
J19: =IF(OR(H19="",I19=""),"",ROUND(H19*I19,0)) | P19: =IF(AND(J19="",M19="",O19=""),"",N(M19)+N(J19)*N(N19)+N(O19)) | Q19: =IF(P19="","",P19/Lists!$C$18) | S19: =IF(OR(P19="",R19=""),"",P19*R19) | U19: =IF(AND(S19="",T19=""),"",N(S19)+N(T19))
J20: =IF(OR(H20="",I20=""),"",ROUND(H20*I20,0)) | P20: =IF(AND(J20="",M20="",O20=""),"",N(M20)+N(J20)*N(N20)+N(O20)) | Q20: =IF(P20="","",P20/Lists!$C$18) | S20: =IF(OR(P20="",R20=""),"",P20*R20) | U20: =IF(AND(S20="",T20=""),"",N(S20)+N(T20))
J21: =IF(OR(H21="",I21=""),"",ROUND(H21*I21,0)) | P21: =IF(AND(J21="",M21="",O21=""),"",N(M21)+N(J21)*N(N21)+N(O21)) | Q21: =IF(P21="","",P21/Lists!$C$18) | S21: =IF(OR(P21="",R21=""),"",P21*R21) | U21: =IF(AND(S21="",T21=""),"",N(S21)+N(T21))
J22: =IF(OR(H22="",I22=""),"",ROUND(H22*I22,0)) | P22: =IF(AND(J22="",M22="",O22=""),"",N(M22)+N(J22)*N(N22)+N(O22)) | Q22: =IF(P22="","",P22/Lists!$C$18) | S22: =IF(OR(P22="",R22=""),"",P22*R22) | U22: =IF(AND(S22="",T22=""),"",N(S22)+N(T22))
J23: =IF(OR(H23="",I23=""),"",ROUND(H23*I23,0)) | P23: =IF(AND(J23="",M23="",O23=""),"",N(M23)+N(J23)*N(N23)+N(O23)) | Q23: =IF(P23="","",P23/Lists!$C$18) | S23: =IF(OR(P23="",R23=""),"",P23*R23) | U23: =IF(AND(S23="",T23=""),"",N(S23)+N(T23))
J24: =IF(OR(H24="",I24=""),"",ROUND(H24*I24,0)) | P24: =IF(AND(J24="",M24="",O24=""),"",N(M24)+N(J24)*N(N24)+N(O24)) | Q24: =IF(P24="","",P24/Lists!$C$18) | S24: =IF(OR(P24="",R24=""),"",P24*R24) | U24: =IF(AND(S24="",T24=""),"",N(S24)+N(T24))
J25: =IF(OR(H25="",I25=""),"",ROUND(H25*I25,0)) | P25: =IF(AND(J25="",M25="",O25=""),"",N(M25)+N(J25)*N(N25)+N(O25)) | Q25: =IF(P25="","",P25/Lists!$C$18) | S25: =IF(OR(P25="",R25=""),"",P25*R25) | U25: =IF(AND(S25="",T25=""),"",N(S25)+N(T25))
... J69: =IF(OR(H69="",I69=""),"",ROUND(H69*I69,0)) | P69: =IF(AND(J69="",M69="",O69=""),"",N(M69)+N(J69)*N(N69)+N(O69)) | Q69: =IF(P69="","",P69/Lists!$C$18) | S69: =IF(OR(P69="",R69=""),"",P69*R69) | U69: =IF(AND(S69="",T69=""),"",N(S69)+N(T69))
B70: IT & Security total | G70: =SUM(G10:G69) | H70: =SUM(H10:H69) | J70: =SUM(J10:J69) | M70: =SUM(M10:M69) | O70: =SUM(O10:O69) | P70: =SUM(P10:P69) | Q70: =SUM(Q10:Q69) | S70: =SUM(S10:S69) | T70: =SUM(T10:T69) | U70: =SUM(U10:U69)

Sheet Legal & Privacy
B1: Legal & Privacy · scope
B4: Every asset, system and deliverable this function owns that the program touches. Blue text on white is yours to fill in. Light-blue cells calculate; leave them as they are.
B6: Replace the example rows, add what's missing, and mark rows Not applicable instead of deleting them.
B8: The item | G8: Volume | K8: Change | M8: Effort | R8: Cost | V8: Readiness | AB8: Risk | AE8: Plan
B9: Asset category | C9: Asset or deliverable | D9: Description or example | E9: Owner | F9: System or location | G9: Total quantity | H9: Active quantity | I9: % needing change | J9: Items to update | K9: Change type | L9: Complexity | M9: One-time setup hours | N9: Avg hours per item | O9: QA and review hours | P9: Total internal hours | Q9: Internal FTE days | R9: Blended hourly rate | S9: Internal cost | T9: External or vendor cost | U9: Total estimated cost | V9: Can bulk update or automate? | W9: Customer action needed? | X9: External notice needed? | Y9: External approval needed? | Z9: Dependency or prerequisite | AA9: Lead time (calendar days) | AB9: Business risk if missed | AC9: Customer disruption | AD9: Old and new run side by side? | AE9: Disposition | AF9: Required timing | AG9: Status | AH9: Notes and assumptions
B10: Policies | C10: Privacy notice | D10: Notice covering the new platform and its processors | E10: Privacy counsel | F10: Website | G10: 250 | H10: 188 | I10: 0.5 | J10: =IF(OR(H10="",I10=""),"",ROUND(H10*I10,0)) | K10: Technical configuration | L10: Low | M10: 24 | N10: 4 | O10: 16 | P10: =IF(AND(J10="",M10="",O10=""),"",N(M10)+N(J10)*N(N10)+N(O10)) | Q10: =IF(P10="","",P10/Lists!$C$18) | R10: 95 | S10: =IF(OR(P10="",R10=""),"",P10*R10) | T10: 12000 | U10: =IF(AND(S10="",T10=""),"",N(S10)+N(T10)) | V10: Partial | W10: Yes | X10: Yes | Y10: No | Z10: Platform choice confirmed | AA10: 45 | AB10: Critical | AC10: Medium | AD10: Partial | AE10: Update | AF10: Before cutover | AG10: Validated | AH10: Example row: replace with your own estimate.
B11: Policies | C11: Cookie consent | D11: Consent tool set-up on the new site | E11: Privacy counsel | F11: Consent platform | G11: 12 | H11: 7 | I11: 0.75 | J11: =IF(OR(H11="",I11=""),"",ROUND(H11*I11,0)) | K11: Technical configuration | L11: Medium | M11: 16 | N11: 0.5 | O11: 8 | P11: =IF(AND(J11="",M11="",O11=""),"",N(M11)+N(J11)*N(N11)+N(O11)) | Q11: =IF(P11="","",P11/Lists!$C$18) | R11: 85 | S11: =IF(OR(P11="",R11=""),"",P11*R11) | U11: =IF(AND(S11="",T11=""),"",N(S11)+N(T11)) | V11: Partial | W11: No | X11: Yes | Y11: Yes | AA11: 14 | AB11: Medium | AC11: Low | AD11: No | AE11: Redirect | AF11: Before cutover | AG11: Validated
B12: Contracts | C12: Order form links | D12: Order forms that point to online terms | E12: Commercial counsel | F12: Contract system | G12: 250 | H12: 225 | I12: 0.75 | J12: =IF(OR(H12="",I12=""),"",ROUND(H12*I12,0)) | K12: Legal text | L12: Critical | M12: 16 | N12: 1 | O12: 16 | P12: =IF(AND(J12="",M12="",O12=""),"",N(M12)+N(J12)*N(N12)+N(O12)) | Q12: =IF(P12="","",P12/Lists!$C$18) | S12: =IF(OR(P12="",R12=""),"",P12*R12) | U12: =IF(AND(S12="",T12=""),"",N(S12)+N(T12)) | V12: Partial | W12: No | X12: Partial | Y12: No | AA12: 14 | AB12: Low | AC12: High | AD12: Partial | AE12: Merge | AF12: Cutover day | AG12: Validated
B13: Vendors | C13: Data processing agreements | D13: Agreement updates for the new hosting vendor | E13: Privacy counsel | F13: Contract system | G13: 25 | H13: 19 | I13: 0.75 | J13: =IF(OR(H13="",I13=""),"",ROUND(H13*I13,0)) | K13: URL / link | L13: Medium | M13: 8 | N13: 4 | O13: 8 | P13: =IF(AND(J13="",M13="",O13=""),"",N(M13)+N(J13)*N(N13)+N(O13)) | Q13: =IF(P13="","",P13/Lists!$C$18) | R13: 85 | S13: =IF(OR(P13="",R13=""),"",P13*R13) | U13: =IF(AND(S13="",T13=""),"",N(S13)+N(T13)) | V13: No | W13: No | X13: Yes | Y13: Yes | AA13: 10 | AB13: Critical | AC13: Medium | AD13: No | AE13: Update | AF13: Before cutover | AG13: Validated
J14: =IF(OR(H14="",I14=""),"",ROUND(H14*I14,0)) | P14: =IF(AND(J14="",M14="",O14=""),"",N(M14)+N(J14)*N(N14)+N(O14)) | Q14: =IF(P14="","",P14/Lists!$C$18) | S14: =IF(OR(P14="",R14=""),"",P14*R14) | U14: =IF(AND(S14="",T14=""),"",N(S14)+N(T14))
J15: =IF(OR(H15="",I15=""),"",ROUND(H15*I15,0)) | P15: =IF(AND(J15="",M15="",O15=""),"",N(M15)+N(J15)*N(N15)+N(O15)) | Q15: =IF(P15="","",P15/Lists!$C$18) | S15: =IF(OR(P15="",R15=""),"",P15*R15) | U15: =IF(AND(S15="",T15=""),"",N(S15)+N(T15))
J16: =IF(OR(H16="",I16=""),"",ROUND(H16*I16,0)) | P16: =IF(AND(J16="",M16="",O16=""),"",N(M16)+N(J16)*N(N16)+N(O16)) | Q16: =IF(P16="","",P16/Lists!$C$18) | S16: =IF(OR(P16="",R16=""),"",P16*R16) | U16: =IF(AND(S16="",T16=""),"",N(S16)+N(T16))
J17: =IF(OR(H17="",I17=""),"",ROUND(H17*I17,0)) | P17: =IF(AND(J17="",M17="",O17=""),"",N(M17)+N(J17)*N(N17)+N(O17)) | Q17: =IF(P17="","",P17/Lists!$C$18) | S17: =IF(OR(P17="",R17=""),"",P17*R17) | U17: =IF(AND(S17="",T17=""),"",N(S17)+N(T17))
J18: =IF(OR(H18="",I18=""),"",ROUND(H18*I18,0)) | P18: =IF(AND(J18="",M18="",O18=""),"",N(M18)+N(J18)*N(N18)+N(O18)) | Q18: =IF(P18="","",P18/Lists!$C$18) | S18: =IF(OR(P18="",R18=""),"",P18*R18) | U18: =IF(AND(S18="",T18=""),"",N(S18)+N(T18))
J19: =IF(OR(H19="",I19=""),"",ROUND(H19*I19,0)) | P19: =IF(AND(J19="",M19="",O19=""),"",N(M19)+N(J19)*N(N19)+N(O19)) | Q19: =IF(P19="","",P19/Lists!$C$18) | S19: =IF(OR(P19="",R19=""),"",P19*R19) | U19: =IF(AND(S19="",T19=""),"",N(S19)+N(T19))
J20: =IF(OR(H20="",I20=""),"",ROUND(H20*I20,0)) | P20: =IF(AND(J20="",M20="",O20=""),"",N(M20)+N(J20)*N(N20)+N(O20)) | Q20: =IF(P20="","",P20/Lists!$C$18) | S20: =IF(OR(P20="",R20=""),"",P20*R20) | U20: =IF(AND(S20="",T20=""),"",N(S20)+N(T20))
J21: =IF(OR(H21="",I21=""),"",ROUND(H21*I21,0)) | P21: =IF(AND(J21="",M21="",O21=""),"",N(M21)+N(J21)*N(N21)+N(O21)) | Q21: =IF(P21="","",P21/Lists!$C$18) | S21: =IF(OR(P21="",R21=""),"",P21*R21) | U21: =IF(AND(S21="",T21=""),"",N(S21)+N(T21))
J22: =IF(OR(H22="",I22=""),"",ROUND(H22*I22,0)) | P22: =IF(AND(J22="",M22="",O22=""),"",N(M22)+N(J22)*N(N22)+N(O22)) | Q22: =IF(P22="","",P22/Lists!$C$18) | S22: =IF(OR(P22="",R22=""),"",P22*R22) | U22: =IF(AND(S22="",T22=""),"",N(S22)+N(T22))
J23: =IF(OR(H23="",I23=""),"",ROUND(H23*I23,0)) | P23: =IF(AND(J23="",M23="",O23=""),"",N(M23)+N(J23)*N(N23)+N(O23)) | Q23: =IF(P23="","",P23/Lists!$C$18) | S23: =IF(OR(P23="",R23=""),"",P23*R23) | U23: =IF(AND(S23="",T23=""),"",N(S23)+N(T23))
J24: =IF(OR(H24="",I24=""),"",ROUND(H24*I24,0)) | P24: =IF(AND(J24="",M24="",O24=""),"",N(M24)+N(J24)*N(N24)+N(O24)) | Q24: =IF(P24="","",P24/Lists!$C$18) | S24: =IF(OR(P24="",R24=""),"",P24*R24) | U24: =IF(AND(S24="",T24=""),"",N(S24)+N(T24))
J25: =IF(OR(H25="",I25=""),"",ROUND(H25*I25,0)) | P25: =IF(AND(J25="",M25="",O25=""),"",N(M25)+N(J25)*N(N25)+N(O25)) | Q25: =IF(P25="","",P25/Lists!$C$18) | S25: =IF(OR(P25="",R25=""),"",P25*R25) | U25: =IF(AND(S25="",T25=""),"",N(S25)+N(T25))
... J69: =IF(OR(H69="",I69=""),"",ROUND(H69*I69,0)) | P69: =IF(AND(J69="",M69="",O69=""),"",N(M69)+N(J69)*N(N69)+N(O69)) | Q69: =IF(P69="","",P69/Lists!$C$18) | S69: =IF(OR(P69="",R69=""),"",P69*R69) | U69: =IF(AND(S69="",T69=""),"",N(S69)+N(T69))
B70: Legal & Privacy total | G70: =SUM(G10:G69) | H70: =SUM(H10:H69) | J70: =SUM(J10:J69) | M70: =SUM(M10:M69) | O70: =SUM(O10:O69) | P70: =SUM(P10:P69) | Q70: =SUM(Q10:Q69) | S70: =SUM(S10:S69) | T70: =SUM(T10:T69) | U70: =SUM(U10:U69)

Sheet Sales Enablement
B1: Sales Enablement · scope
B4: Every asset, system and deliverable this function owns that the program touches. Blue text on white is yours to fill in. Light-blue cells calculate; leave them as they are.
B6: Replace the example rows, add what's missing, and mark rows Not applicable instead of deleting them.
B8: The item | G8: Volume | K8: Change | M8: Effort | R8: Cost | V8: Readiness | AB8: Risk | AE8: Plan
B9: Asset category | C9: Asset or deliverable | D9: Description or example | E9: Owner | F9: System or location | G9: Total quantity | H9: Active quantity | I9: % needing change | J9: Items to update | K9: Change type | L9: Complexity | M9: One-time setup hours | N9: Avg hours per item | O9: QA and review hours | P9: Total internal hours | Q9: Internal FTE days | R9: Blended hourly rate | S9: Internal cost | T9: External or vendor cost | U9: Total estimated cost | V9: Can bulk update or automate? | W9: Customer action needed? | X9: External notice needed? | Y9: External approval needed? | Z9: Dependency or prerequisite | AA9: Lead time (calendar days) | AB9: Business risk if missed | AC9: Customer disruption | AD9: Old and new run side by side? | AE9: Disposition | AF9: Required timing | AG9: Status | AH9: Notes and assumptions
B10: Templates | C10: Proposal templates | D10: Proposals with portal screenshots and links | E10: Enablement lead | F10: Content hub | G10: 12 | H10: 7 | I10: 0.5 | J10: =IF(OR(H10="",I10=""),"",ROUND(H10*I10,0)) | K10: Multiple changes | L10: High | M10: 24 | N10: 1 | O10: 4 | P10: =IF(AND(J10="",M10="",O10=""),"",N(M10)+N(J10)*N(N10)+N(O10)) | Q10: =IF(P10="","",P10/Lists!$C$18) | R10: 95 | S10: =IF(OR(P10="",R10=""),"",P10*R10) | T10: 30000 | U10: =IF(AND(S10="",T10=""),"",N(S10)+N(T10)) | V10: No | W10: No | X10: Partial | Y10: Yes | Z10: Platform choice confirmed | AA10: 14 | AB10: Low | AC10: Medium | AD10: No | AE10: Merge | AF10: Cutover day | AG10: Validated | AH10: Example row: replace with your own estimate.
B11: Training | C11: Sales training modules | D11: Courses that demo the portal | E11: Enablement lead | F11: Learning platform | G11: 60 | H11: 54 | I11: 0.75 | J11: =IF(OR(H11="",I11=""),"",ROUND(H11*I11,0)) | K11: Multiple changes | L11: Critical | M11: 24 | N11: 4 | O11: 4 | P11: =IF(AND(J11="",M11="",O11=""),"",N(M11)+N(J11)*N(N11)+N(O11)) | Q11: =IF(P11="","",P11/Lists!$C$18) | R11: 85 | S11: =IF(OR(P11="",R11=""),"",P11*R11) | T11: 12000 | U11: =IF(AND(S11="",T11=""),"",N(S11)+N(T11)) | V11: No | W11: No | X11: Yes | Y11: No | AA11: 10 | AB11: Critical | AC11: Critical | AD11: Partial | AE11: Merge | AF11: 31–90 days | AG11: Scoping
B12: Collateral | C12: Product one-pagers | D12: Sell sheets with URLs and QR codes | E12: Enablement lead | F12: Content hub | G12: 4 | H12: 4 | I12: 0.25 | J12: =IF(OR(H12="",I12=""),"",ROUND(H12*I12,0)) | K12: Content update | L12: Low | M12: 4 | N12: 0.5 | O12: 4 | P12: =IF(AND(J12="",M12="",O12=""),"",N(M12)+N(J12)*N(N12)+N(O12)) | Q12: =IF(P12="","",P12/Lists!$C$18) | R12: 95 | S12: =IF(OR(P12="",R12=""),"",P12*R12) | T12: 30000 | U12: =IF(AND(S12="",T12=""),"",N(S12)+N(T12)) | V12: No | W12: Yes | X12: Yes | Y12: No | AA12: 45 | AB12: Medium | AC12: Low | AD12: Yes | AE12: Redirect | AF12: Before cutover | AG12: Not started
J13: =IF(OR(H13="",I13=""),"",ROUND(H13*I13,0)) | P13: =IF(AND(J13="",M13="",O13=""),"",N(M13)+N(J13)*N(N13)+N(O13)) | Q13: =IF(P13="","",P13/Lists!$C$18) | S13: =IF(OR(P13="",R13=""),"",P13*R13) | U13: =IF(AND(S13="",T13=""),"",N(S13)+N(T13))
J14: =IF(OR(H14="",I14=""),"",ROUND(H14*I14,0)) | P14: =IF(AND(J14="",M14="",O14=""),"",N(M14)+N(J14)*N(N14)+N(O14)) | Q14: =IF(P14="","",P14/Lists!$C$18) | S14: =IF(OR(P14="",R14=""),"",P14*R14) | U14: =IF(AND(S14="",T14=""),"",N(S14)+N(T14))
J15: =IF(OR(H15="",I15=""),"",ROUND(H15*I15,0)) | P15: =IF(AND(J15="",M15="",O15=""),"",N(M15)+N(J15)*N(N15)+N(O15)) | Q15: =IF(P15="","",P15/Lists!$C$18) | S15: =IF(OR(P15="",R15=""),"",P15*R15) | U15: =IF(AND(S15="",T15=""),"",N(S15)+N(T15))
J16: =IF(OR(H16="",I16=""),"",ROUND(H16*I16,0)) | P16: =IF(AND(J16="",M16="",O16=""),"",N(M16)+N(J16)*N(N16)+N(O16)) | Q16: =IF(P16="","",P16/Lists!$C$18) | S16: =IF(OR(P16="",R16=""),"",P16*R16) | U16: =IF(AND(S16="",T16=""),"",N(S16)+N(T16))
J17: =IF(OR(H17="",I17=""),"",ROUND(H17*I17,0)) | P17: =IF(AND(J17="",M17="",O17=""),"",N(M17)+N(J17)*N(N17)+N(O17)) | Q17: =IF(P17="","",P17/Lists!$C$18) | S17: =IF(OR(P17="",R17=""),"",P17*R17) | U17: =IF(AND(S17="",T17=""),"",N(S17)+N(T17))
J18: =IF(OR(H18="",I18=""),"",ROUND(H18*I18,0)) | P18: =IF(AND(J18="",M18="",O18=""),"",N(M18)+N(J18)*N(N18)+N(O18)) | Q18: =IF(P18="","",P18/Lists!$C$18) | S18: =IF(OR(P18="",R18=""),"",P18*R18) | U18: =IF(AND(S18="",T18=""),"",N(S18)+N(T18))
J19: =IF(OR(H19="",I19=""),"",ROUND(H19*I19,0)) | P19: =IF(AND(J19="",M19="",O19=""),"",N(M19)+N(J19)*N(N19)+N(O19)) | Q19: =IF(P19="","",P19/Lists!$C$18) | S19: =IF(OR(P19="",R19=""),"",P19*R19) | U19: =IF(AND(S19="",T19=""),"",N(S19)+N(T19))
J20: =IF(OR(H20="",I20=""),"",ROUND(H20*I20,0)) | P20: =IF(AND(J20="",M20="",O20=""),"",N(M20)+N(J20)*N(N20)+N(O20)) | Q20: =IF(P20="","",P20/Lists!$C$18) | S20: =IF(OR(P20="",R20=""),"",P20*R20) | U20: =IF(AND(S20="",T20=""),"",N(S20)+N(T20))
J21: =IF(OR(H21="",I21=""),"",ROUND(H21*I21,0)) | P21: =IF(AND(J21="",M21="",O21=""),"",N(M21)+N(J21)*N(N21)+N(O21)) | Q21: =IF(P21="","",P21/Lists!$C$18) | S21: =IF(OR(P21="",R21=""),"",P21*R21) | U21: =IF(AND(S21="",T21=""),"",N(S21)+N(T21))
J22: =IF(OR(H22="",I22=""),"",ROUND(H22*I22,0)) | P22: =IF(AND(J22="",M22="",O22=""),"",N(M22)+N(J22)*N(N22)+N(O22)) | Q22: =IF(P22="","",P22/Lists!$C$18) | S22: =IF(OR(P22="",R22=""),"",P22*R22) | U22: =IF(AND(S22="",T22=""),"",N(S22)+N(T22))
J23: =IF(OR(H23="",I23=""),"",ROUND(H23*I23,0)) | P23: =IF(AND(J23="",M23="",O23=""),"",N(M23)+N(J23)*N(N23)+N(O23)) | Q23: =IF(P23="","",P23/Lists!$C$18) | S23: =IF(OR(P23="",R23=""),"",P23*R23) | U23: =IF(AND(S23="",T23=""),"",N(S23)+N(T23))
J24: =IF(OR(H24="",I24=""),"",ROUND(H24*I24,0)) | P24: =IF(AND(J24="",M24="",O24=""),"",N(M24)+N(J24)*N(N24)+N(O24)) | Q24: =IF(P24="","",P24/Lists!$C$18) | S24: =IF(OR(P24="",R24=""),"",P24*R24) | U24: =IF(AND(S24="",T24=""),"",N(S24)+N(T24))
... J69: =IF(OR(H69="",I69=""),"",ROUND(H69*I69,0)) | P69: =IF(AND(J69="",M69="",O69=""),"",N(M69)+N(J69)*N(N69)+N(O69)) | Q69: =IF(P69="","",P69/Lists!$C$18) | S69: =IF(OR(P69="",R69=""),"",P69*R69) | U69: =IF(AND(S69="",T69=""),"",N(S69)+N(T69))
B70: Sales Enablement total | G70: =SUM(G10:G69) | H70: =SUM(H10:H69) | J70: =SUM(J10:J69) | M70: =SUM(M10:M69) | O70: =SUM(O10:O69) | P70: =SUM(P10:P69) | Q70: =SUM(Q10:Q69) | S70: =SUM(S10:S69) | T70: =SUM(T10:T69) | U70: =SUM(U10:U69)

Sheet Sales & RevOps
B1: Sales & RevOps · scope
B4: Every asset, system and deliverable this function owns that the program touches. Blue text on white is yours to fill in. Light-blue cells calculate; leave them as they are.
B6: Replace the example rows, add what's missing, and mark rows Not applicable instead of deleting them.
B8: The item | G8: Volume | K8: Change | M8: Effort | R8: Cost | V8: Readiness | AB8: Risk | AE8: Plan
B9: Asset category | C9: Asset or deliverable | D9: Description or example | E9: Owner | F9: System or location | G9: Total quantity | H9: Active quantity | I9: % needing change | J9: Items to update | K9: Change type | L9: Complexity | M9: One-time setup hours | N9: Avg hours per item | O9: QA and review hours | P9: Total internal hours | Q9: Internal FTE days | R9: Blended hourly rate | S9: Internal cost | T9: External or vendor cost | U9: Total estimated cost | V9: Can bulk update or automate? | W9: Customer action needed? | X9: External notice needed? | Y9: External approval needed? | Z9: Dependency or prerequisite | AA9: Lead time (calendar days) | AB9: Business risk if missed | AC9: Customer disruption | AD9: Old and new run side by side? | AE9: Disposition | AF9: Required timing | AG9: Status | AH9: Notes and assumptions
B10: CRM | C10: Email sequences | D10: Sales sequences with portal links | E10: RevOps manager | F10: CRM | G10: 120 | H10: 120 | I10: 1 | J10: =IF(OR(H10="",I10=""),"",ROUND(H10*I10,0)) | K10: URL / link | L10: Medium | M10: 16 | N10: 1 | O10: 8 | P10: =IF(AND(J10="",M10="",O10=""),"",N(M10)+N(J10)*N(N10)+N(O10)) | Q10: =IF(P10="","",P10/Lists!$C$18) | R10: 95 | S10: =IF(OR(P10="",R10=""),"",P10*R10) | T10: 5000 | U10: =IF(AND(S10="",T10=""),"",N(S10)+N(T10)) | V10: Partial | W10: Yes | X10: No | Y10: Yes | Z10: Platform choice confirmed | AA10: 45 | AB10: Low | AC10: Medium | AD10: Partial | AE10: Update | AF10: 31–90 days | AG10: Scoping | AH10: Example row: replace with your own estimate.
B11: CRM | C11: Quote templates | D11: Quotes with links to online terms | E11: RevOps manager | F11: Quoting tool | G11: 40 | H11: 36 | I11: 0.5 | J11: =IF(OR(H11="",I11=""),"",ROUND(H11*I11,0)) | K11: Visual update | L11: Medium | M11: 8 | N11: 2 | O11: 2 | P11: =IF(AND(J11="",M11="",O11=""),"",N(M11)+N(J11)*N(N11)+N(O11)) | Q11: =IF(P11="","",P11/Lists!$C$18) | R11: 85 | S11: =IF(OR(P11="",R11=""),"",P11*R11) | U11: =IF(AND(S11="",T11=""),"",N(S11)+N(T11)) | V11: No | W11: No | X11: No | Y11: No | AA11: 60 | AB11: Medium | AC11: Medium | AD11: Yes | AE11: Retire | AF11: 0–30 days | AG11: Not started
B12: Reporting | C12: Pipeline dashboards | D12: Dashboards that track portal sign-ups | E12: RevOps analyst | F12: BI tool | G12: 800 | H12: 800 | I12: 0.75 | J12: =IF(OR(H12="",I12=""),"",ROUND(H12*I12,0)) | K12: Full rebuild | L12: Critical | M12: 16 | N12: 2 | O12: 16 | P12: =IF(AND(J12="",M12="",O12=""),"",N(M12)+N(J12)*N(N12)+N(O12)) | Q12: =IF(P12="","",P12/Lists!$C$18) | S12: =IF(OR(P12="",R12=""),"",P12*R12) | T12: 30000 | U12: =IF(AND(S12="",T12=""),"",N(S12)+N(T12)) | V12: No | W12: No | X12: Yes | Y12: No | AA12: 45 | AB12: High | AC12: Critical | AD12: Yes | AE12: Redirect | AF12: Before cutover | AG12: Not started
J13: =IF(OR(H13="",I13=""),"",ROUND(H13*I13,0)) | P13: =IF(AND(J13="",M13="",O13=""),"",N(M13)+N(J13)*N(N13)+N(O13)) | Q13: =IF(P13="","",P13/Lists!$C$18) | S13: =IF(OR(P13="",R13=""),"",P13*R13) | U13: =IF(AND(S13="",T13=""),"",N(S13)+N(T13))
J14: =IF(OR(H14="",I14=""),"",ROUND(H14*I14,0)) | P14: =IF(AND(J14="",M14="",O14=""),"",N(M14)+N(J14)*N(N14)+N(O14)) | Q14: =IF(P14="","",P14/Lists!$C$18) | S14: =IF(OR(P14="",R14=""),"",P14*R14) | U14: =IF(AND(S14="",T14=""),"",N(S14)+N(T14))
J15: =IF(OR(H15="",I15=""),"",ROUND(H15*I15,0)) | P15: =IF(AND(J15="",M15="",O15=""),"",N(M15)+N(J15)*N(N15)+N(O15)) | Q15: =IF(P15="","",P15/Lists!$C$18) | S15: =IF(OR(P15="",R15=""),"",P15*R15) | U15: =IF(AND(S15="",T15=""),"",N(S15)+N(T15))
J16: =IF(OR(H16="",I16=""),"",ROUND(H16*I16,0)) | P16: =IF(AND(J16="",M16="",O16=""),"",N(M16)+N(J16)*N(N16)+N(O16)) | Q16: =IF(P16="","",P16/Lists!$C$18) | S16: =IF(OR(P16="",R16=""),"",P16*R16) | U16: =IF(AND(S16="",T16=""),"",N(S16)+N(T16))
J17: =IF(OR(H17="",I17=""),"",ROUND(H17*I17,0)) | P17: =IF(AND(J17="",M17="",O17=""),"",N(M17)+N(J17)*N(N17)+N(O17)) | Q17: =IF(P17="","",P17/Lists!$C$18) | S17: =IF(OR(P17="",R17=""),"",P17*R17) | U17: =IF(AND(S17="",T17=""),"",N(S17)+N(T17))
J18: =IF(OR(H18="",I18=""),"",ROUND(H18*I18,0)) | P18: =IF(AND(J18="",M18="",O18=""),"",N(M18)+N(J18)*N(N18)+N(O18)) | Q18: =IF(P18="","",P18/Lists!$C$18) | S18: =IF(OR(P18="",R18=""),"",P18*R18) | U18: =IF(AND(S18="",T18=""),"",N(S18)+N(T18))
J19: =IF(OR(H19="",I19=""),"",ROUND(H19*I19,0)) | P19: =IF(AND(J19="",M19="",O19=""),"",N(M19)+N(J19)*N(N19)+N(O19)) | Q19: =IF(P19="","",P19/Lists!$C$18) | S19: =IF(OR(P19="",R19=""),"",P19*R19) | U19: =IF(AND(S19="",T19=""),"",N(S19)+N(T19))
